  0%|                                                                                                                                | 0/18 [00:00<?, ?it/s]Traceback (most recent call last):
  File "/user_data/amulyam/Projects/LLaVA/FineTune/train/train.py", line 991, in <module>
    train()
  File "/user_data/amulyam/Projects/LLaVA/FineTune/train/train.py", line 969, in train
    trainer.train()
  File "/home/amulyam/miniconda3/envs/llava/lib/python3.10/site-packages/transformers/trainer.py", line 1539, in train
    return inner_training_loop(
  File "/home/amulyam/miniconda3/envs/llava/lib/python3.10/site-packages/transformers/trainer.py", line 1836, in _inner_training_loop
    for step, inputs in enumerate(epoch_iterator):
  File "/home/amulyam/miniconda3/envs/llava/lib/python3.10/site-packages/accelerate/data_loader.py", line 452, in __iter__
    current_batch = next(dataloader_iter)
  File "/home/amulyam/miniconda3/envs/llava/lib/python3.10/site-packages/torch/utils/data/dataloader.py", line 630, in __next__
    data = self._next_data()
  File "/home/amulyam/miniconda3/envs/llava/lib/python3.10/site-packages/torch/utils/data/dataloader.py", line 1345, in _next_data
    return self._process_data(data)
  File "/home/amulyam/miniconda3/envs/llava/lib/python3.10/site-packages/torch/utils/data/dataloader.py", line 1371, in _process_data
    data.reraise()
  File "/home/amulyam/miniconda3/envs/llava/lib/python3.10/site-packages/torch/_utils.py", line 694, in reraise
    raise exception
FileNotFoundError: Caught FileNotFoundError in DataLoader worker process 0.
Original Traceback (most recent call last):
  File "/home/amulyam/miniconda3/envs/llava/lib/python3.10/site-packages/torch/utils/data/_utils/worker.py", line 308, in _worker_loop
    data = fetcher.fetch(index)
  File "/home/amulyam/miniconda3/envs/llava/lib/python3.10/site-packages/torch/utils/data/_utils/fetch.py", line 51, in fetch
    data = [self.dataset[idx] for idx in possibly_batched_index]
  File "/home/amulyam/miniconda3/envs/llava/lib/python3.10/site-packages/torch/utils/data/_utils/fetch.py", line 51, in <listcomp>
    data = [self.dataset[idx] for idx in possibly_batched_index]
  File "/user_data/amulyam/Projects/LLaVA/FineTune/train/train.py", line 701, in __getitem__
    image = Image.open(os.path.join(image_folder, image_file)).convert('RGB')
  File "/home/amulyam/miniconda3/envs/llava/lib/python3.10/site-packages/PIL/Image.py", line 3431, in open
    fp = builtins.open(filename, "rb")
FileNotFoundError: [Errno 2] No such file or directory: '/user_data/amulyam/Projects/SciCOT/ai2d/ai2d/images/4307.png'

Traceback (most recent call last):
  File "/user_data/amulyam/Projects/LLaVA/FineTune/train/train.py", line 991, in <module>
    train()
  File "/user_data/amulyam/Projects/LLaVA/FineTune/train/train.py", line 969, in train
    trainer.train()
  File "/home/amulyam/miniconda3/envs/llava/lib/python3.10/site-packages/transformers/trainer.py", line 1539, in train
    return inner_training_loop(
  File "/home/amulyam/miniconda3/envs/llava/lib/python3.10/site-packages/transformers/trainer.py", line 1836, in _inner_training_loop
    for step, inputs in enumerate(epoch_iterator):
  File "/home/amulyam/miniconda3/envs/llava/lib/python3.10/site-packages/accelerate/data_loader.py", line 452, in __iter__
    current_batch = next(dataloader_iter)
  File "/home/amulyam/miniconda3/envs/llava/lib/python3.10/site-packages/torch/utils/data/dataloader.py", line 630, in __next__
    data = self._next_data()
  File "/home/amulyam/miniconda3/envs/llava/lib/python3.10/site-packages/torch/utils/data/dataloader.py", line 1345, in _next_data
    return self._process_data(data)
  File "/home/amulyam/miniconda3/envs/llava/lib/python3.10/site-packages/torch/utils/data/dataloader.py", line 1371, in _process_data
    data.reraise()
  File "/home/amulyam/miniconda3/envs/llava/lib/python3.10/site-packages/torch/_utils.py", line 694, in reraise
    raise exception
FileNotFoundError: Caught FileNotFoundError in DataLoader worker process 0.
Original Traceback (most recent call last):
  File "/home/amulyam/miniconda3/envs/llava/lib/python3.10/site-packages/torch/utils/data/_utils/worker.py", line 308, in _worker_loop
    data = fetcher.fetch(index)
  File "/home/amulyam/miniconda3/envs/llava/lib/python3.10/site-packages/torch/utils/data/_utils/fetch.py", line 51, in fetch
    data = [self.dataset[idx] for idx in possibly_batched_index]
  File "/home/amulyam/miniconda3/envs/llava/lib/python3.10/site-packages/torch/utils/data/_utils/fetch.py", line 51, in <listcomp>
    data = [self.dataset[idx] for idx in possibly_batched_index]
  File "/user_data/amulyam/Projects/LLaVA/FineTune/train/train.py", line 701, in __getitem__
    image = Image.open(os.path.join(image_folder, image_file)).convert('RGB')
  File "/home/amulyam/miniconda3/envs/llava/lib/python3.10/site-packages/PIL/Image.py", line 3431, in open
    fp = builtins.open(filename, "rb")
FileNotFoundError: [Errno 2] No such file or directory: '/user_data/amulyam/Projects/SciCOT/ai2d/ai2d/images/4307.png'
